<mujoco model="ur5e">
  <compiler angle="radian" meshdir="assets" autolimits="true"/>

  <option integrator="implicitfast" timestep="0.005"/>

  <default>
    <default class="ur5e">
      <material specular="0.5" shininess="0.25"/>
      <joint armature="0.1" damping="1.0" axis="0 1 0" range="-3.1415926 3.1415926"/>
      <general dyntype="none" biastype="affine"/>
      <default class="visual">
        <geom type="mesh" contype="0" conaffinity="0" group="2"/>
      </default>
      <default class="collision">
        <geom type="capsule" group="3"/>
        <default class="eef_collision">
          <geom type="cylinder"/>
        </default>
      </default>
      <site size="0.001" rgba="0.5 0.5 0.5 0.3" group="4"/>

    </default>
  </default>

<asset>
    <material class="ur5e" name="black" rgba="0.033 0.033 0.033 1"/>
    <material class="ur5e" name="jointgray" rgba="0.278 0.278 0.278 1"/>
    <material class="ur5e" name="linkgray" rgba="0.82 0.82 0.82 1"/>
    <material class="ur5e" name="urblue" rgba="0.49 0.678 0.8 1"/>
    <mesh file="base_0.obj"/> <mesh file="base_1.obj"/>
    <mesh file="shoulder_0.obj"/> <mesh file="shoulder_1.obj"/> <mesh file="shoulder_2.obj"/>
    <mesh file="upperarm_0.obj"/> <mesh file="upperarm_1.obj"/> <mesh file="upperarm_2.obj"/> <mesh file="upperarm_3.obj"/>
    <mesh file="forearm_0.obj"/> <mesh file="forearm_1.obj"/> <mesh file="forearm_2.obj"/> <mesh file="forearm_3.obj"/>
    <mesh file="wrist1_0.obj"/> <mesh file="wrist1_1.obj"/> <mesh file="wrist1_2.obj"/>
    <mesh file="wrist2_0.obj"/> <mesh file="wrist2_1.obj"/> <mesh file="wrist2_2.obj"/>
    <mesh file="wrist3.obj"/>
  </asset>

  <worldbody>
    <light name="spotlight" mode="targetbodycom" target="wrist_2_link" pos="0 -1 2"/>
    <body name="base" quat="1 0 0 0" childclass="ur5e">
      <inertial mass="4.0" pos="0 0 0" diaginertia="0.00443333156 0.00443333156 0.0072"/>
      <geom mesh="base_0" material="black" class="visual"/>
      <geom mesh="base_1" material="jointgray" class="visual"/>
      <body name="shoulder_link" pos="0 0 0.163">
        <inertial mass="3.7" pos="0 0 0" diaginertia="0.0102675 0.0102675 0.00666"/>
        <joint name="shoulder_pan_joint" class="ur5e" axis="0 0 1"/>
        <geom mesh="shoulder_0" material="urblue" class="visual"/>
        <geom mesh="shoulder_1" material="black" class="visual"/>
        <geom mesh="shoulder_2" material="jointgray" class="visual"/>
        <geom class="collision" size="0.06 0.06" pos="0 0 -0.04"/>
        <body name="upper_arm_link" pos="0 0.138 0" quat="1 0 1 0">
          <inertial mass="8.393" pos="0 0 0.2125" diaginertia="0.133886 0.133886 0.0151074"/>
          <joint name="shoulder_lift_joint" class="ur5e"/>
          <geom mesh="upperarm_0" material="linkgray" class="visual"/>
          <geom mesh="upperarm_1" material="black" class="visual"/>
          <geom mesh="upperarm_2" material="jointgray" class="visual"/>
          <geom mesh="upperarm_3" material="urblue" class="visual"/>
          <geom class="collision" pos="0 -0.04 0" quat="1 1 0 0" size="0.06 0.06"/>
          <geom class="collision" size="0.05 0.2" pos="0 0 0.2"/>
          <body name="forearm_link" pos="0 -0.131 0.425">
            <inertial mass="2.275" pos="0 0 0.196" diaginertia="0.0311796 0.0311796 0.004095"/>
            <joint name="elbow_joint" class="ur5e"/>
            <geom mesh="forearm_0" material="urblue" class="visual"/>
            <geom mesh="forearm_1" material="linkgray" class="visual"/>
            <geom mesh="forearm_2" material="black" class="visual"/>
            <geom mesh="forearm_3" material="jointgray" class="visual"/>
            <geom class="collision" pos="0 0.08 0" quat="1 1 0 0" size="0.055 0.06"/>
            <geom class="collision" size="0.038 0.19" pos="0 0 0.2"/>
            <body name="wrist_1_link" pos="0 0 0.392" quat="1 0 1 0">
              <inertial mass="1.219" pos="0 0.127 0" diaginertia="0.0025599 0.0025599 0.0021942"/>
              <joint name="wrist_1_joint" class="ur5e"/>
              <geom mesh="wrist1_0" material="black" class="visual"/>
              <geom mesh="wrist1_1" material="urblue" class="visual"/>
              <geom mesh="wrist1_2" material="jointgray" class="visual"/>
              <geom class="collision" pos="0 0.05 0" quat="1 1 0 0" size="0.04 0.07"/>
              <body name="wrist_2_link" pos="0 0.127 0">
                <inertial mass="1.219" pos="0 0 0.1" diaginertia="0.0025599 0.0025599 0.0021942"/>
                <joint name="wrist_2_joint" axis="0 0 1" class="ur5e"/>
                <geom mesh="wrist2_0" material="black" class="visual"/>
                <geom mesh="wrist2_1" material="urblue" class="visual"/>
                <geom mesh="wrist2_2" material="jointgray" class="visual"/>
                <geom class="collision" size="0.04 0.06" pos="0 0 0.04"/>
                <geom class="collision" pos="0 0.02 0.1" quat="1 1 0 0" size="0.04 0.04"/>
                <body name="wrist_3_link" pos="0 0 0.1">
                  <inertial mass="0.1889" pos="0 0.0771683 0" quat="1 0 0 1"
                    diaginertia="0.000132134 9.90863e-05 9.90863e-05"/>
                  <joint name="wrist_3_joint" class="ur5e"/>
                  <geom material="linkgray" mesh="wrist3" class="visual"/>
                  <geom class="eef_collision" pos="0 0.08 0" quat="1 1 0 0" size="0.04 0.02"/>
                  <site name="attachment_site" pos="0 0.1 0" quat="-1 1 0 0"/>

                  <body name="force_sensor" pos="0 0.1 0" euler="3.14 0 3.14">
                    <geom name='force_sensor_geom'
                          type="sphere"
                          mass="0.01"
                          size="0.04"
                          rgba="0 1 0 0.3"
                          contype="1"
                          conaffinity="1"
                          group="2"/>
                    <site name="force_sensor_site" pos="0 0 0" quat="1 0 0 0"/>
                  </body>
                </body>
              </body>
            </body>
          </body>
        </body>
      </body>
    </body>
    <body name="world_frame" pos="0 0 0">
            <geom name="X" type="cylinder" size="0.005" fromto="0 0 0 0.3 0 0" rgba="1 0 0 1" contype="0"
                  conaffinity="0"/>
            <geom name="Y" type="cylinder" size="0.005" fromto="0 0 0 0 0.3 0" rgba="0 1 0 1" contype="0"
                  conaffinity="0"/>
            <geom name="Z" type="cylinder" size="0.005" fromto="0 0 0 0 0 0.3" rgba="0 0 1 1" contype="0"
                  conaffinity="0"/>
    </body>

  </worldbody>
  <sensor>
    <force site="force_sensor_site"/>
  </sensor>
  <actuator>
    <general class="ur5e" name="pos_shoulder_pan"  joint="shoulder_pan_joint"  gainprm="6000" biasprm="0 -6000 -600"/>
    <general class="ur5e" name="pos_shoulder_lift" joint="shoulder_lift_joint" gainprm="6000" biasprm="0 -6000 -600"/>
    <general class="ur5e" name="pos_elbow"         joint="elbow_joint"         gainprm="4000" biasprm="0 -4000 -400"/>
    <general class="ur5e" name="pos_wrist_1"       joint="wrist_1_joint"       gainprm="1000" biasprm="0 -1000 -100"/>
    <general class="ur5e" name="pos_wrist_2"       joint="wrist_2_joint"       gainprm="1000" biasprm="0 -1000 -100"/>
    <general class="ur5e" name="pos_wrist_3"       joint="wrist_3_joint"       gainprm="500" biasprm="0 -500 -50"/>

    <motor class="ur5e" name="trq_shoulder_pan"  joint="shoulder_pan_joint" ctrlrange="-150 150"/>
    <motor class="ur5e" name="trq_shoulder_lift" joint="shoulder_lift_joint" ctrlrange="-150 150"/>
    <motor class="ur5e" name="trq_elbow"         joint="elbow_joint"         ctrlrange="-150 150"/>
    <motor class="ur5e" name="trq_wrist_1"       joint="wrist_1_joint"       ctrlrange="-28 28"/>
    <motor class="ur5e" name="trq_wrist_2"       joint="wrist_2_joint"       ctrlrange="-28 28"/>
    <motor class="ur5e" name="trq_wrist_3"       joint="wrist_3_joint"       ctrlrange="-28 28"/>
  </actuator>

  <keyframe>
    <key name="home" qpos="-1.63 -1.37 2.47 -1.54 -3.14 0" ctrl="-1.63 -1.37 2.47 -1.54 -3.14 0 0 0 0 0 0 0 "/>
  </keyframe>
</mujoco>
